<?xml version="1.0" encoding="UTF-8"?>
<robot name="lizi_description"
  xmlns:controller="http://playerstage.sourceforge.net/gazebo/xmlschema/#controller" 
  xmlns:interface="http://playerstage.sourceforge.net/gazebo/xmlschema/#interface" 
  xmlns:sensor="http://playerstage.sourceforge.net/gazebo/xmlschema/#sensor" 
  xmlns:xacro="http://playerstage.sourceforge.net/gazebo/xmlschema/#interface">

  <!-- ================================================================= -->
  <!-- Xacro properties ================================================ -->
  <!-- ================================================================= -->

  <!-- <xacro:arg name="robot_id" value="1" /> -->

  <!-- ================================================================= -->
  <!-- URDF Model ====================================================== -->
  <!-- ================================================================= -->

  <link name="base_link">
    <inertial>
      <origin xyz="0.00740029995582005 -2.28205996951805E-05 -0.0185383676881744" rpy="0 0 0" />
      <mass value="2.737825665359006" />
      <inertia ixx="0.00443729503022144" ixy="-0.000146932517007627" ixz="0.000385689591614384" iyy="0.0102726152318081" iyz="2.25160881374285E-06" izz="0.0122176381167974" />
    </inertial>
    <visual>
      <origin xyz="0 0 0" rpy="0 0 0" />
      <geometry>
        <mesh filename="package://lizi_description/meshes/base_link_light.dae" />
      </geometry>
      <material name="">
        <color rgba="0.792156862745098 0.819607843137255 0.933333333333333 1" />
      </material>
    </visual>
    <collision>
      <origin xyz="0 0 0" rpy="0 0 0" />
      <geometry>
        <mesh filename="package://lizi_description/meshes/base_link_light.dae" />
      </geometry>
    </collision>
  </link>
  <link name="FL_wheel">
    <inertial>
      <origin xyz="1.22832299886966E-13 -0.0437656188895607 -2.26337004693988E-12" rpy="0 0 0" />
      <mass value="0.628863260607655" />
      <inertia ixx="0.0011775370427045" ixy="-5.42894125322565E-16" ixz="-1.02893303220018E-12" iyy="0.00215242721820778" iyz="-9.13724670627397E-14" izz="0.00117753703821153" />
    </inertial>
    <visual>
      <origin xyz="0 0 0" rpy="0 0 0" />
      <geometry>
        <mesh filename="package://lizi_description/meshes/FL_wheel.STL" />
      </geometry>
      <material name="">
        <color rgba="0.776470588235294 0.756862745098039 0.737254901960784 1" />
      </material>
    </visual>
    <collision>
      <origin xyz="0 0 0" rpy="0 0 0" />
      <geometry>
        <mesh filename="package://lizi_description/meshes/FL_wheel.STL" />
      </geometry>
    </collision>
  </link>
  <joint name="front_left_joint" type="continuous">
    <origin xyz="0.074003 0.1825 -0.04145" rpy="0 0 0" />
    <parent link="base_link" />
    <child link="FL_wheel" />
    <axis xyz="0 1 0" />
  </joint>
  <link name="RL_Wheel">
    <inertial>
      <origin xyz="-0.199999999999878 -0.0437656188895606 -2.26411944748151E-12" rpy="0 0 0" />
      <mass value="0.628863260607654" />
      <inertia ixx="0.0011775370427045" ixy="-5.42922210117761E-16" ixz="-1.02893248605437E-12" iyy="0.00215242721820777" iyz="-9.13722944336042E-14" izz="0.00117753703821152" />
    </inertial>
    <visual>
      <origin xyz="0 0 0" rpy="0 0 0" />
      <geometry>
        <mesh filename="package://lizi_description/meshes/RL_Wheel.STL" />
      </geometry>
      <material name="">
        <color rgba="0.776470588235294 0.756862745098039 0.737254901960784 1" />
      </material>
    </visual>
    <collision>
      <origin xyz="0 0 0" rpy="0 0 0" />
      <geometry>
        <mesh filename="package://lizi_description/meshes/RL_Wheel.STL" />
      </geometry>
    </collision>
  </link>
  <joint name="rear_left_joint" type="continuous">
    <origin xyz="-0.126 0.1825 -0.04145" rpy="0 0 0" />
    <parent link="base_link" />
    <child link="RL_Wheel" />
    <axis xyz="0 1 0" />
  </joint>
  <link name="FR_Wheel">
    <inertial>
      <origin xyz="-2.04403161063738E-12 0.0437656188895606 -9.79660796929238E-13" rpy="0 0 0" />
      <mass value="0.628863260607655" />
      <inertia ixx="0.00117753703838158" ixy="7.98742831623608E-14" ixz="1.33933241813037E-12" iyy="0.00215242721820778" iyz="4.43766701026677E-14" izz="0.00117753704253445" />
    </inertial>
    <visual>
      <origin xyz="0 0 0" rpy="0 0 0" />
      <geometry>
        <mesh filename="package://lizi_description/meshes/FR_Wheel.STL" />
      </geometry>
      <material name="">
        <color rgba="0.776470588235294 0.756862745098039 0.737254901960784 1" />
      </material>
    </visual>
    <collision>
      <origin xyz="0 0 0" rpy="0 0 0" />
      <geometry>
        <mesh filename="package://lizi_description/meshes/FR_Wheel.STL" />
      </geometry>
    </collision>
  </link>
  <joint name="front_right_joint" type="continuous">
    <origin xyz="0.074003 -0.1825 -0.04145" rpy="-1.0694E-16 1.4202E-32 0" />
    <parent link="base_link" />
    <child link="FR_Wheel" />
    <axis xyz="0 1 0" />
  </joint>
  <link name="RR_Wheel">
    <inertial>
      <origin xyz="2.59875454489134E-12 0.0437656188895579 1.03773240001104E-12" rpy="0 0 0" />
      <mass value="0.628863260607702" />
      <inertia ixx="0.00117753704180015" ixy="-9.03407278285203E-14" ixz="-1.98182107521996E-12" iyy="0.00215242721820778" iyz="-2.17479773270897E-15" izz="0.00117753703911603" />
    </inertial>
    <visual>
      <origin xyz="0 0 0" rpy="0 0 0" />
      <geometry>
        <mesh filename="package://lizi_description/meshes/RR_Wheel.STL" />
      </geometry>
      <material name="">
        <color rgba="0.776470588235294 0.756862745098039 0.737254901960784 1" />
      </material>
    </visual>
    <collision>
      <origin xyz="0 0 0" rpy="0 0 0" />
      <geometry>
        <mesh filename="package://lizi_description/meshes/RR_Wheel.STL" />
      </geometry>
    </collision>
  </link>
  <joint name="rear_right_joint" type="continuous">
    <origin xyz="-0.126 -0.1825 -0.04145" rpy="-1.0694E-16 1.4202E-32 0" />
    <parent link="base_link" />
    <child link="RR_Wheel" />
    <axis xyz="0 1 0" />
  </joint>


  <!-- ================================================================= -->
  <!-- Gazebo references =============================================== -->
  <!-- ================================================================= -->


  <gazebo reference="base_link">
    <material>Gazebo/Gold</material>
  </gazebo>

  <gazebo reference="RR_Wheel">
    <material>Gazebo/FlatBlack</material>
  </gazebo>

  <gazebo reference="RL_Wheel">
    <material>Gazebo/FlatBlack</material>
  </gazebo>

  <gazebo reference="FR_Wheel">
    <material>Gazebo/FlatBlack</material>
  </gazebo>

  <gazebo reference="FL_wheel">
    <material>Gazebo/FlatBlack</material>
  </gazebo>

  <gazebo>
    <link name="hokuyo_link">
      <pose>0 0 0.09 0 0 0</pose>
      <inertial>
        <mass>0.1</mass>
        <inertia>
          <ixx>0.000166666666</ixx> <ixy>0</ixy> <ixz>0</ixz>
                       <iyy>0.000166666666</iyy> <iyz>0</iyz>
                                    <izz>0.000166666666</izz>
        </inertia>
      </inertial>
      <visual name="visual">
        <geometry>
          <mesh>
            <uri>model://hokuyo/meshes/hokuyo.dae</uri>
          </mesh>
        </geometry>
      </visual>
      <sensor name="laser" type="ray">
        <always_on>1</always_on>
        <update_rate>40</update_rate>       
        <visualize>false</visualize>

        <pose>0.00 0 0.0175 0 0 0</pose>
        <ray>
          <scan>
            <horizontal>
              <samples>1040</samples>
              <resolution>1</resolution>
              <min_angle>-2.26889</min_angle>
              <max_angle>2.268899</max_angle>
            </horizontal>
          </scan>
          <range>
            <min>0.08</min>
            <max>30</max>
            <resolution>0.01</resolution>
          </range>
          <!-- Add noise to each beam -->
          <!--<noise>
             <type>gaussian</type>
             <mean>0.0</mean>
             <stddev>0.01</stddev>
          </noise>-->
        </ray>

        <plugin name="laser" filename="libRayPlugin.so" />        

        <plugin name="gazebo_ros_laser_controller" filename="libgazebo_ros_laser.so">          
          <alwaysOn>true</alwaysOn>
          <updateRate>40</updateRate>
          <topicName>base_scan</topicName>
          <frameName>laser_link</frameName>          
        </plugin>                
      </sensor>
    </link>

    <joint name="body_to_hokuyo" type="revolute">
      <child>hokuyo_link</child>
      <parent>base_link</parent>
      <axis>
        <xyz>0 0 1</xyz>
        <limit>
          <upper>0</upper>
          <lower>0</lower>
        </limit>
      </axis>
    </joint>

  </gazebo>


  <gazebo>
    <plugin name="skid_steer_drive_controller" filename="libgazebo_ros_skid_steer_drive.so">
      <updateRate>100.0</updateRate>     
      <leftFrontJoint>front_left_joint</leftFrontJoint>
      <rightFrontJoint>front_right_joint</rightFrontJoint>
      <leftRearJoint>rear_left_joint</leftRearJoint>
      <rightRearJoint>rear_right_joint</rightRearJoint>
      <wheelSeparation>0.255</wheelSeparation>
      <wheelDiameter>0.154</wheelDiameter>
      <odometryTopic>odom</odometryTopic>
      <odometryFrame>odom</odometryFrame>
      <robotBaseFrame>base_link</robotBaseFrame>
      <torque>500</torque>
      <commandTopic>cmd_vel</commandTopic>
      <broadcastTF>1</broadcastTF>
    </plugin>
  

     <plugin name="p3d_base_controller" filename="libgazebo_ros_p3d.so">
       <alwaysOn>true</alwaysOn>
       <updateRate>100.0</updateRate>
       <bodyName>base_link</bodyName>
       <topicName>base_pose_ground_truth</topicName>
       <gaussianNoise>0</gaussianNoise>
       <frameName>/map</frameName>
       <xyzOffsets>0 0 0</xyzOffsets> 
       <rpyOffsets>0 0 0</rpyOffsets>    
     </plugin>   
      
  </gazebo>
 
</robot>
