<?xml version="1.0" ?>
<!-- =================================================================================== -->
<!-- |    This document was autogenerated by xacro from /home/blackpc/open-source-workspaces/models/src/lizi_description/models/lizi.xacro | -->
<!-- |    EDITING THIS FILE BY HAND IS NOT RECOMMENDED                                 | -->
<!-- =================================================================================== -->
<sdf version="1.4" xmlns:controller="http://playerstage.sourceforge.net/gazebo/xmlschema/#controller" xmlns:interface="http://playerstage.sourceforge.net/gazebo/xmlschema/#interface" xmlns:sensor="http://playerstage.sourceforge.net/gazebo/xmlschema/#sensor" xmlns:xacro="http://playerstage.sourceforge.net/gazebo/xmlschema/#interface">
  <world name="default">
    <light name="sun" type="directional">
      <cast_shadows>1</cast_shadows>
      <pose>0 0 10 0 -0 0</pose>
      <diffuse>0.8 0.8 0.8 1</diffuse>
      <specular>0.2 0.2 0.2 1</specular>
      <attenuation>
        <range>1000</range>
        <constant>0.9</constant>
        <linear>0.01</linear>
        <quadratic>0.001</quadratic>
      </attenuation>
      <direction>0.5 0.1 -0.9</direction>
    </light>
    <model name="ground_plane">
      <static>1</static>
      <link name="link">
        <collision name="collision">
          <geometry>
            <plane>
              <normal>0 0 1</normal>
              <size>100 100</size>
            </plane>
          </geometry>
          <surface>
            <friction>
              <ode>
                <mu>100</mu>
                <mu2>50</mu2>
              </ode>
            </friction>
            <bounce/>
            <contact>
              <ode/>
            </contact>
          </surface>
          <max_contacts>10</max_contacts>
        </collision>
        <!-- <visual name='visual'>
          <cast_shadows>0</cast_shadows>

          <geometry>
            <plane>
              <normal>0 0 1</normal>
              <size>100 100</size>
            </plane>
          </geometry>
        </visual> -->
        <velocity_decay>
          <linear>0</linear>
          <angular>0</angular>
        </velocity_decay>
        <self_collide>0</self_collide>
        <kinematic>0</kinematic>
        <gravity>1</gravity>
      </link>
    </model>
    <physics type="ode">
      <max_step_size>0.001</max_step_size>
      <real_time_factor>1</real_time_factor>
      <real_time_update_rate>1000</real_time_update_rate>
      <gravity>0 0 -9.8</gravity>
    </physics>
    <scene>
      <ambient>0.4 0.4 0.4 1</ambient>
      <background>0.7 0.7 0.7 1</background>
      <shadows>1</shadows>
    </scene>
    <model name="lizi_urdf">
      <link name="base_link">
        <pose>0.00740029995582005 -2.28205996951805E-05 -0.0185383676881744 0 0 0</pose>
        <inertial>
          <pose>0 0 0.1 0 0 0</pose>
          <mass>0.737826</mass>
          <inertia>
            <ixx>0.0044373</ixx>
            <ixy>-0.000146933</ixy>
            <ixz>0.00038569</ixz>
            <iyy>0.0102726</iyy>
            <iyz>2.25161e-06</iyz>
            <izz>0.0122176</izz>
          </inertia>
        </inertial>
        <collision name="base_link_collision">
          <pose>0 0 0 0 0 0</pose>
          <geometry>
            <mesh>
              <scale>1 1 1</scale>
              <uri>/home/blackpc/open-source-workspaces/models/src/lizi_description/meshes/base_link.STL</uri>
            </mesh>
          </geometry>
          <max_contacts>10</max_contacts>
          <surface>
            <bounce/>
            <friction>
              <ode/>
            </friction>
            <contact>
              <ode/>
            </contact>
          </surface>
        </collision>
        <visual name="base_link_visual">
          <pose>0 0 0 0 -0 0</pose>
          <geometry>
            <mesh>
              <scale>1 1 1</scale>
              <uri>/home/blackpc/open-source-workspaces/models/src/lizi_description/meshes/base_link.STL</uri>
            </mesh>
          </geometry>
          <material>
            <script>
              <uri>file://media/materials/scripts/gazebo.material</uri>
              <name>Gazebo/Gold</name>
            </script>
          </material>
        </visual>
        <velocity_decay>
          <linear>0</linear>
          <angular>0</angular>
        </velocity_decay>
        <self_collide>0</self_collide>
        <kinematic>0</kinematic>
        <gravity>1</gravity>
      </link>
      <link name="FL_wheel">
        <pose>0.074003 0.1825 -0.04145 0 -0 0</pose>
        <inertial>
          <pose>1.22832e-13 -0.0437656 -2.26337e-12 0 -0 0</pose>
          <mass>0.628863</mass>
          <inertia>
            <ixx>0.00117754</ixx>
            <ixy>-5.42894e-16</ixy>
            <ixz>-1.02893e-12</ixz>
            <iyy>0.00215243</iyy>
            <iyz>-9.13725e-14</iyz>
            <izz>0.00117754</izz>
          </inertia>
        </inertial>
        <collision name="FL_wheel_collision">
          <pose>0 0 0 0 -0 0</pose>
          <geometry>
            <mesh>
              <scale>1 1 1</scale>
              <uri>/home/blackpc/open-source-workspaces/models/src/lizi_description/meshes/FL_wheel.STL</uri>
            </mesh>
          </geometry>
          <max_contacts>10</max_contacts>
          <surface>
            <bounce/>
            <friction>
              <ode/>
            </friction>
            <contact>
              <ode/>
            </contact>
          </surface>
        </collision>
        <visual name="FL_wheel_visual">
          <pose>0 0 0 0 -0 0</pose>
          <geometry>
            <mesh>
              <scale>1 1 1</scale>
              <uri>/home/blackpc/open-source-workspaces/models/src/lizi_description/meshes/FL_wheel.STL</uri>
            </mesh>
          </geometry>
          <material>
            <script>
              <uri>file://media/materials/scripts/gazebo.material</uri>
              <name>Gazebo/FlatBlack</name>
            </script>
          </material>
        </visual>
        <velocity_decay>
          <linear>0</linear>
          <angular>0</angular>
        </velocity_decay>
        <self_collide>0</self_collide>
        <kinematic>0</kinematic>
        <gravity>1</gravity>
      </link>
      <joint name="FL_Joint" type="revolute">
        <child>FL_wheel</child>
        <parent>base_link</parent>
        <axis>
          <xyz>0 1 0</xyz>
          <limit>
            <lower>-1e+16</lower>
            <upper>1e+16</upper>
          </limit>
          <dynamics/>
        </axis>
      </joint>
      <link name="FR_Wheel">
        <pose>0.074003 -0.1825 -0.04145 -1.0694e-16 1.4202e-32 0</pose>
        <inertial>
          <pose>-2.04403e-12 0.0437656 -9.79661e-13 0 -0 0</pose>
          <mass>0.628863</mass>
          <inertia>
            <ixx>0.00117754</ixx>
            <ixy>7.98743e-14</ixy>
            <ixz>1.33933e-12</ixz>
            <iyy>0.00215243</iyy>
            <iyz>4.43767e-14</iyz>
            <izz>0.00117754</izz>
          </inertia>
        </inertial>
        <collision name="FR_Wheel_collision">
          <pose>0 0 0 0 -0 0</pose>
          <geometry>
            <mesh>
              <scale>1 1 1</scale>
              <uri>/home/blackpc/open-source-workspaces/models/src/lizi_description/meshes/FR_Wheel.STL</uri>
            </mesh>
          </geometry>
          <max_contacts>10</max_contacts>
          <surface>
            <bounce/>
            <friction>
              <ode/>
            </friction>
            <contact>
              <ode/>
            </contact>
          </surface>
        </collision>
        <visual name="FR_Wheel_visual">
          <pose>0 0 0 0 -0 0</pose>
          <geometry>
            <mesh>
              <scale>1 1 1</scale>
              <uri>/home/blackpc/open-source-workspaces/models/src/lizi_description/meshes/FR_Wheel.STL</uri>
            </mesh>
          </geometry>
          <material>
            <script>
              <uri>file://media/materials/scripts/gazebo.material</uri>
              <name>Gazebo/FlatBlack</name>
            </script>
          </material>
        </visual>
        <velocity_decay>
          <linear>0</linear>
          <angular>0</angular>
        </velocity_decay>
        <self_collide>0</self_collide>
        <kinematic>0</kinematic>
        <gravity>1</gravity>
      </link>
      <joint name="FR_Joint" type="revolute">
        <child>FR_Wheel</child>
        <parent>base_link</parent>
        <axis>
          <xyz>0 1 0</xyz>
          <limit>
            <lower>-1e+16</lower>
            <upper>1e+16</upper>
          </limit>
          <dynamics/>
        </axis>
      </joint>
      <link name="RL_Wheel">
        <pose>-0.126 0.1825 -0.04145 0 -0 0</pose>
        <inertial>
          <pose>0 -0.0437656 0 0 -0 0</pose>
          <mass>0.628863</mass>
          <inertia>
            <ixx>0.00117754</ixx>
            <ixy>-5.42922e-16</ixy>
            <ixz>-1.02893e-12</ixz>
            <iyy>0.00215243</iyy>
            <iyz>-9.13723e-14</iyz>
            <izz>0.00117754</izz>
          </inertia>
        </inertial>
        <collision name="RL_Wheel_collision">
          <pose>0 0 0 0 -0 0</pose>
          <geometry>
            <mesh>
              <scale>1 1 1</scale>
              <uri>/home/blackpc/open-source-workspaces/models/src/lizi_description/meshes/RL_Wheel.STL</uri>
            </mesh>
          </geometry>
          <max_contacts>10</max_contacts>
          <surface>
            <bounce/>
            <friction>
              <ode/>
            </friction>
            <contact>
              <ode/>
            </contact>
          </surface>
        </collision>
        <visual name="RL_Wheel_visual">
          <pose>0 0 0 0 -0 0</pose>
          <geometry>
            <mesh>
              <scale>1 1 1</scale>
              <uri>/home/blackpc/open-source-workspaces/models/src/lizi_description/meshes/RL_Wheel.STL</uri>
            </mesh>
          </geometry>
          <material>
            <script>
              <uri>file://media/materials/scripts/gazebo.material</uri>
              <name>Gazebo/FlatBlack</name>
            </script>
          </material>
        </visual>
        <velocity_decay>
          <linear>0</linear>
          <angular>0</angular>
        </velocity_decay>
        <self_collide>0</self_collide>
        <kinematic>0</kinematic>
        <gravity>1</gravity>
      </link>
      <joint name="RL_Joint" type="revolute">
        <child>RL_Wheel</child>
        <parent>base_link</parent>
        <axis>
          <xyz>0 1 0</xyz>
          <limit>
            <lower>-1e+16</lower>
            <upper>1e+16</upper>
          </limit>
          <dynamics/>
        </axis>
      </joint>
      <link name="RR_Wheel">
        <pose>-0.126 -0.1825 -0.04145 -1.0694e-16 1.4202e-32 0</pose>
        <inertial>
          <pose>0 0.0437656 0 0 -0 0</pose>
          <mass>0.628863</mass>
          <inertia>
            <ixx>0.00117754</ixx>
            <ixy>-9.03407e-14</ixy>
            <ixz>-1.98182e-12</ixz>
            <iyy>0.00215243</iyy>
            <iyz>-2.1748e-15</iyz>
            <izz>0.00117754</izz>
          </inertia>
        </inertial>
        <collision name="RR_Wheel_collision">
          <pose>0 0 0 0 -0 0</pose>
          <geometry>
            <mesh>
              <scale>1 1 1</scale>
              <uri>/home/blackpc/open-source-workspaces/models/src/lizi_description/meshes/RR_Wheel.STL</uri>
            </mesh>
          </geometry>
          <max_contacts>10</max_contacts>
          <surface>
            <bounce/>
            <friction>
              <ode/>
            </friction>
            <contact>
              <ode/>
            </contact>
          </surface>
        </collision>
        <visual name="RR_Wheel_visual">
          <pose>0 0 0 0 -0 0</pose>
          <geometry>
            <mesh>
              <scale>1 1 1</scale>
              <uri>/home/blackpc/open-source-workspaces/models/src/lizi_description/meshes/RR_Wheel.STL</uri>
            </mesh>
          </geometry>
          <material>
            <script>
              <uri>file://media/materials/scripts/gazebo.material</uri>
              <name>Gazebo/FlatBlack</name>
            </script>
          </material>
        </visual>
        <velocity_decay>
          <linear>0</linear>
          <angular>0</angular>
        </velocity_decay>
        <self_collide>0</self_collide>
        <kinematic>0</kinematic>
        <gravity>1</gravity>
      </link>
      <joint name="RR_Joint" type="revolute">
        <child>RR_Wheel</child>
        <parent>base_link</parent>
        <axis>
          <xyz>0 1 0</xyz>
          <limit>
            <lower>-1e+16</lower>
            <upper>1e+16</upper>
          </limit>
          <dynamics/>
        </axis>
      </joint>
      <pose>0 0 1 0 -0 0</pose>
      <static>0</static>
      <link name="hokuyo::link">
        <inertial>
          <mass>0.1</mass>
          <inertia>
            <ixx>1</ixx>
            <ixy>0</ixy>
            <ixz>0</ixz>
            <iyy>1</iyy>
            <iyz>0</iyz>
            <izz>1</izz>
          </inertia>
        </inertial>
        <visual name="visual">
          <geometry>
            <mesh>
              <uri>/home/blackpc/open-source-workspaces/models/src/lizi_description/meshes/hokuyo.dae</uri>
            </mesh>
          </geometry>
        </visual>
        <collision name="collision-base">
          <pose>0 0 -0.0145 0 -0 0</pose>
          <geometry>
            <box>
              <size>0.05 0.05 0.041</size>
            </box>
          </geometry>
          <max_contacts>10</max_contacts>
          <surface>
            <bounce/>
            <friction>
              <ode/>
            </friction>
            <contact>
              <ode/>
            </contact>
          </surface>
        </collision>
        <collision name="collision-top">
          <pose>0 0 0.0205 0 -0 0</pose>
          <geometry>
            <cylinder>
              <radius>0.021</radius>
              <length>0.029</length>
            </cylinder>
          </geometry>
          <max_contacts>10</max_contacts>
          <surface>
            <bounce/>
            <friction>
              <ode/>
            </friction>
            <contact>
              <ode/>
            </contact>
          </surface>
        </collision>
        <sensor name="laser" type="ray">
          <pose>0 0 0 0 -0 0</pose>
          <ray>
            <scan>
              <horizontal>
                <samples>1040</samples>
                <resolution>1</resolution>
                <min_angle>-2.26889</min_angle>
                <max_angle>2.2689</max_angle>
              </horizontal>
            </scan>
            <range>
              <min>0.1</min>
              <max>30</max>
              <resolution>0.01</resolution>
            </range>
          </ray>
          <plugin filename="libgazebo_ros_laser.so" name="gazebo_ros_hokuyo_laser_controller">
            <gaussianNoise>0.01</gaussianNoise>
            <alwaysOn>true</alwaysOn>
            <hokuyoMinIntensity>101</hokuyoMinIntensity>
            <updateRate>40.0</updateRate>
            <topicName>/lizi/scan_raw</topicName>
            <frameName>/lizi/odom_tf</frameName>
            <interface:laser/>
          </plugin>
          <always_on>1</always_on>
          <update_rate>30</update_rate>
          <visualize>0</visualize>
        </sensor>
        <velocity_decay>
          <linear>0</linear>
          <angular>0</angular>
        </velocity_decay>
        <pose>0 0 0.1 0 -0 0</pose>
        <self_collide>0</self_collide>
        <kinematic>0</kinematic>
        <gravity>1</gravity>
      </link>
      <joint name="hokuyo_joint" type="revolute">
        <child>hokuyo::link</child>
        <parent>base_link</parent>
        <axis>
          <xyz>0 0 1</xyz>
          <limit>
            <upper>0</upper>
            <lower>0</lower>
          </limit>
        </axis>
      </joint>
      <plugin filename="libgazebo_ros_skid_steer_drive.so" name="skid_steer_drive_controller">
        <updateRate>100.0</updateRate>
        <robotNamespace>/lizi</robotNamespace>
        <commandTopic>/lizi/cmd_vel</commandTopic>
        <leftFrontJoint>FL_Joint</leftFrontJoint>
        <rightFrontJoint>FR_Joint</rightFrontJoint>
        <leftRearJoint>RL_Joint</leftRearJoint>
        <rightRearJoint>RR_Joint</rightRearJoint>
        <wheelSeparation>0.3650</wheelSeparation>
        <wheelDiameter>0.155</wheelDiameter>
        <odometryTopic>odom_raw</odometryTopic>
        <robotBaseFrame>/odom_tf</robotBaseFrame>
        <torque>120</torque>
        <odometryFrame>cmd_vel_raw</odometryFrame>
        <broadcastTF>1</broadcastTF>
      </plugin>
    </model>
    <model name="willowgarage">
      <static>1</static>
      <pose>-11 -29 0 0 -0 0</pose>
      <link name="walls">
        <collision name="collision">
          <geometry>
            <mesh>
              <uri>/home/blackpc/open-source-workspaces/models/src/lizi_description/meshes/willowgarage_collision.dae</uri>
            </mesh>
          </geometry>
          <max_contacts>10</max_contacts>
          <surface>
            <bounce/>
            <friction>
              <ode/>
            </friction>
            <contact>
              <ode/>
            </contact>
          </surface>
        </collision>
        <visual name="visual">
          <geometry>
            <mesh>
              <uri>/home/blackpc/open-source-workspaces/models/src/lizi_description/meshes/willowgarage_visual.dae</uri>
            </mesh>
          </geometry>
          <cast_shadows>0</cast_shadows>
        </visual>
        <velocity_decay>
          <linear>0</linear>
          <angular>0</angular>
        </velocity_decay>
        <self_collide>0</self_collide>
        <kinematic>0</kinematic>
        <gravity>1</gravity>
      </link>
    </model>
  </world>
</sdf>
